Workbook

Sheet Cómo usar
A1: Planilla semanal de horarios · GESTLOK
B2: EJEMPLO CON DATOS FICTICIOS (demo de GESTLOK). Ninguna persona ni local es real.
B4: 1 | C4: Pestaña «Equipo»: cargá a tu gente una sola vez (nombre, puesto, si cobra por horas o por turnos y cuántas horas vale un OFF).
B5: 2 | C5: Pestaña «Semana»: escribí el local y la fecha del lunes. Los días, las fechas y los feriados se completan solos.
B6: 3 | C6: Cargá entrada y salida con formato 10:00. Si trabaja de mañana y de noche, cargá los dos turnos. Si sale pasada la medianoche (ej. 01:00), se calcula bien.
B7: 4 | C7: En «Estado» elegí OFF, Feriado, Ausente, Ausente justificado o Vacaciones. «Feriado» es cuando la persona trabajó ese día feriado. Si trabajó un día normal, dejalo vacío.
B8: 5 | C8: Pestaña «Resumen»: total de la semana de cada persona (trabajado, OFF, feriado, ausentes y vacaciones), listo para imprimir o enviar.
B9: 6 | C9: Nueva semana: duplicá el archivo o la pestaña, borrá los horarios celestes y cambiá la fecha del lunes.
B10: 7 | C10: Para usarla en GESTLOK: subila a tu Google Drive, abrila con Google Sheets y pegá su enlace en Administrar a los empleados › Horarios.
B12: Colores
C13: Celeste: celdas para completar
C14: Blanco: se calcula solo
C15: Ámbar: feriado
C16: Rojo: OFF
C17: Gris: ausente
C18: Verde: vacaciones
B20: Cómo se calcula
C21: Horas del día (quienes cobran por horas) = (salida − entrada) del turno mañana + la del turno noche.
C22: Turnos (quienes cobran por turnos): cada horario de entrada cargado suma 1 turno, de mañana o de noche.
C23: OFF: por horas suma las «horas que paga» de la pestaña Equipo; por turnos suma 1 turno.
C24: Feriado: se paga aparte, además de lo trabajado (horas o turnos de ese día).
C25: Total a liquidar = Trabajado + OFF + Feriado. Ausentes y vacaciones se informan en días.

Sheet Semana
A1: Planilla semanal de horarios · GESTLOK
D2: Local | E2: Mercado Central | G2: Semana desde (lunes) | I2: 46349 | J2: hasta | K2: =I2+6 -> 46355 | M2: Celeste = completar
A4: Colaborador | B4: Detalle | C4: =CHOOSE(WEEKDAY(C5,2),"Lunes","Martes","Miércoles","Jueves","Viernes","Sábado","Domingo") -> Lunes | D4: =CHOOSE(WEEKDAY(D5,2),"Lunes","Martes","Miércoles","Jueves","Viernes","Sábado","Domingo") -> Martes | E4: =CHOOSE(WEEKDAY(E5,2),"Lunes","Martes","Miércoles","Jueves","Viernes","Sábado","Domingo") -> Miércoles | F4: =CHOOSE(WEEKDAY(F5,2),"Lunes","Martes","Miércoles","Jueves","Viernes","Sábado","Domingo") -> Jueves | G4: =CHOOSE(WEEKDAY(G5,2),"Lunes","Martes","Miércoles","Jueves","Viernes","Sábado","Domingo") -> Viernes | H4: =CHOOSE(WEEKDAY(H5,2),"Lunes","Martes","Miércoles","Jueves","Viernes","Sábado","Domingo") -> Sábado | I4: =CHOOSE(WEEKDAY(I5,2),"Lunes","Martes","Miércoles","Jueves","Viernes","Sábado","Domingo") -> Domingo | J4: Horas trabajadas | K4: Turnos | L4: OFF (días) | M4: Feriado | N4: Ausentes (días) | O4: Total a liquidar (trab. + OFF + fer.) | Q4: Cobra por | R4: Horas OFF | S4: Horas en feriado | T4: Turnos en feriado | U4: Total horas | V4: Total turnos
C5: =$I$2 -> 46349 | D5: =C5+1 -> 46350 | E5: =D5+1 -> 46351 | F5: =E5+1 -> 46352 | G5: =F5+1 -> 46353 | H5: =G5+1 -> 46354 | I5: =H5+1 -> 46355
C6: =IF(COUNTIFS(Feriados!$A$5:$A$60,C5,Feriados!$C$5:$C$60,"Feriado")>0,"Feriado","") -> Feriado | D6: =IF(COUNTIFS(Feriados!$A$5:$A$60,D5,Feriados!$C$5:$C$60,"Feriado")>0,"Feriado","") | E6: =IF(COUNTIFS(Feriados!$A$5:$A$60,E5,Feriados!$C$5:$C$60,"Feriado")>0,"Feriado","") | F6: =IF(COUNTIFS(Feriados!$A$5:$A$60,F5,Feriados!$C$5:$C$60,"Feriado")>0,"Feriado","") | G6: =IF(COUNTIFS(Feriados!$A$5:$A$60,G5,Feriados!$C$5:$C$60,"Feriado")>0,"Feriado","") | H6: =IF(COUNTIFS(Feriados!$A$5:$A$60,H5,Feriados!$C$5:$C$60,"Feriado")>0,"Feriado","") | I6: =IF(COUNTIFS(Feriados!$A$5:$A$60,I5,Feriados!$C$5:$C$60,"Feriado")>0,"Feriado","")
A7: =IFERROR(INDEX(Equipo!$B$5:$B$14,1)&"","") -> Sofía Ríos | B7: Mañana · entrada | C7: 0.375 | D7: 0.375 | E7: 0.375 | G7: 0.375 | H7: 0.375 | I7: 0.41666667 | J7: =IF($Q7="Turnos","",SUM(C12:I12)) | K7: =SUMPRODUCT(((C7:I7<>"")+(C9:I9<>""))*((C11:I11="")+(C11:I11="Feriado"))) -> 6 | L7: =COUNTIF(C11:I11,"OFF") -> 1 | M7: =IF($A7="","",IF($Q7="Horas",IF($S7=0,"–",TEXT($S7,"[h]:mm")&" hs"),IF($T7=0,"–",$T7&IF($T7=1," turno"," turnos")))) -> 1 turno | N7: =COUNTIF(C11:I11,"Ausente") -> 0 | O7: =IF($A7="","",IF($Q7="Horas",TEXT($U7,"[h]:mm")&" hs",$V7&IF($V7=1," turno"," turnos"))) -> 8 turnos | Q7: =IFERROR(INDEX(Equipo!$D$5:$D$14,1)&"","") -> Turnos | R7: =N(INDEX(Equipo!$E$5:$E$14,1)) -> 1 | S7: =SUMPRODUCT(C12:I12*(C11:I11="Feriado")) -> 0.25 | T7: =COUNTIFS(C11:I11,"Feriado",C7:I7,"<>")+COUNTIFS(C11:I11,"Feriado",C9:I9,"<>") -> 1 | U7: =N(J7)+L7*R7+S7 -> 1.25 | V7: =K7+L7+T7 -> 8
A8: =IF($A7="","",INDEX(Equipo!$C$5:$C$14,1)&"") -> Encargada | B8: Mañana · salida | C8: 0.625 | D8: 0.625 | E8: 0.625 | G8: 0.625 | H8: 0.625 | I8: 0.58333333
A9: =IF($A7="","","Cobra por "&LOWER(INDEX(Equipo!$D$5:$D$14,1))) -> Cobra por turnos | B9: Noche · entrada
B10: Noche · salida
B11: Estado | C11: Feriado | F11: OFF
B12: Horas del día | C12: =IF(AND(C11<>"",C11<>"Feriado"),0,IF(AND(C7<>"",C8<>""),MOD(C8-C7,1),0)+IF(AND(C9<>"",C10<>""),MOD(C10-C9,1),0)) -> 0.25 | D12: =IF(AND(D11<>"",D11<>"Feriado"),0,IF(AND(D7<>"",D8<>""),MOD(D8-D7,1),0)+IF(AND(D9<>"",D10<>""),MOD(D10-D9,1),0)) -> 0.25 | E12: =IF(AND(E11<>"",E11<>"Feriado"),0,IF(AND(E7<>"",E8<>""),MOD(E8-E7,1),0)+IF(AND(E9<>"",E10<>""),MOD(E10-E9,1),0)) -> 0.25 | F12: =IF(AND(F11<>"",F11<>"Feriado"),0,IF(AND(F7<>"",F8<>""),MOD(F8-F7,1),0)+IF(AND(F9<>"",F10<>""),MOD(F10-F9,1),0)) -> 0 | G12: =IF(AND(G11<>"",G11<>"Feriado"),0,IF(AND(G7<>"",G8<>""),MOD(G8-G7,1),0)+IF(AND(G9<>"",G10<>""),MOD(G10-G9,1),0)) -> 0.25 | H12: =IF(AND(H11<>"",H11<>"Feriado"),0,IF(AND(H7<>"",H8<>""),MOD(H8-H7,1),0)+IF(AND(H9<>"",H10<>""),MOD(H10-H9,1),0)) -> 0.25 | I12: =IF(AND(I11<>"",I11<>"Feriado"),0,IF(AND(I7<>"",I8<>""),MOD(I8-I7,1),0)+IF(AND(I9<>"",I10<>""),MOD(I10-I9,1),0)) -> 0.16666667
A14: =IFERROR(INDEX(Equipo!$B$5:$B$14,2)&"","") -> Lucas Ferreyra | B14: Mañana · entrada | J14: =IF($Q14="Turnos","",SUM(C19:I19)) | K14: =SUMPRODUCT(((C14:I14<>"")+(C16:I16<>""))*((C18:I18="")+(C18:I18="Feriado"))) -> 6 | L14: =COUNTIF(C18:I18,"OFF") -> 1 | M14: =IF($A14="","",IF($Q14="Horas",IF($S14=0,"–",TEXT($S14,"[h]:mm")&" hs"),IF($T14=0,"–",$T14&IF($T14=1," turno"," turnos")))) -> – | N14: =COUNTIF(C18:I18,"Ausente") -> 0 | O14: =IF($A14="","",IF($Q14="Horas",TEXT($U14,"[h]:mm")&" hs",$V14&IF($V14=1," turno"," turnos"))) -> 7 turnos | Q14: =IFERROR(INDEX(Equipo!$D$5:$D$14,2)&"","") -> Turnos | R14: =N(INDEX(Equipo!$E$5:$E$14,2)) -> 1 | S14: =SUMPRODUCT(C19:I19*(C18:I18="Feriado")) -> 0 | T14: =COUNTIFS(C18:I18,"Feriado",C14:I14,"<>")+COUNTIFS(C18:I18,"Feriado",C16:I16,"<>") -> 0 | U14: =N(J14)+L14*R14+S14 -> 1 | V14: =K14+L14+T14 -> 7
A15: =IF($A14="","",INDEX(Equipo!$C$5:$C$14,2)&"") -> Encargado | B15: Mañana · salida
A16: =IF($A14="","","Cobra por "&LOWER(INDEX(Equipo!$D$5:$D$14,2))) -> Cobra por turnos | B16: Noche · entrada | D16: 0.75 | E16: 0.75 | F16: 0.75 | G16: 0.75 | H16: 0.75 | I16: 0.75
B17: Noche · salida | D17: 0.97916667 | E17: 0.97916667 | F17: 0.97916667 | G17: 0.020833333 | H17: 0.041666667 | I17: 0.95833333
B18: Estado | C18: OFF
B19: Horas del día | C19: =IF(AND(C18<>"",C18<>"Feriado"),0,IF(AND(C14<>"",C15<>""),MOD(C15-C14,1),0)+IF(AND(C16<>"",C17<>""),MOD(C17-C16,1),0)) -> 0 | D19: =IF(AND(D18<>"",D18<>"Feriado"),0,IF(AND(D14<>"",D15<>""),MOD(D15-D14,1),0)+IF(AND(D16<>"",D17<>""),MOD(D17-D16,1),0)) -> 0.22916667 | E19: =IF(AND(E18<>"",E18<>"Feriado"),0,IF(AND(E14<>"",E15<>""),MOD(E15-E14,1),0)+IF(AND(E16<>"",E17<>""),MOD(E17-E16,1),0)) -> 0.22916667 | F19: =IF(AND(F18<>"",F18<>"Feriado"),0,IF(AND(F14<>"",F15<>""),MOD(F15-F14,1),0)+IF(AND(F16<>"",F17<>""),MOD(F17-F16,1),0)) -> 0.22916667 | G19: =IF(AND(G18<>"",G18<>"Feriado"),0,IF(AND(G14<>"",G15<>""),MOD(G15-G14,1),0)+IF(AND(G16<>"",G17<>""),MOD(G17-G16,1),0)) -> 0.27083333 | H19: =IF(AND(H18<>"",H18<>"Feriado"),0,IF(AND(H14<>"",H15<>""),MOD(H15-H14,1),0)+IF(AND(H16<>"",H17<>""),MOD(H17-H16,1),0)) -> 0.29166667 | I19: =IF(AND(I18<>"",I18<>"Feriado"),0,IF(AND(I14<>"",I15<>""),MOD(I15-I14,1),0)+IF(AND(I16<>"",I17<>""),MOD(I17-I16,1),0)) -> 0.20833333
A21: =IFERROR(INDEX(Equipo!$B$5:$B$14,3)&"","") -> Brenda Quiroga | B21: Mañana · entrada | C21: 0.41666667 | D21: 0.41666667 | F21: 0.41666667 | G21: 0.41666667 | H21: 0.41666667 | J21: =IF($Q21="Turnos","",SUM(C26:I26)) | K21: =SUMPRODUCT(((C21:I21<>"")+(C23:I23<>""))*((C25:I25="")+(C25:I25="Feriado"))) -> 9 | L21: =COUNTIF(C25:I25,"OFF") -> 1 | M21: =IF($A21="","",IF($Q21="Horas",IF($S21=0,"–",TEXT($S21,"[h]:mm")&" hs"),IF($T21=0,"–",$T21&IF($T21=1," turno"," turnos")))) -> 2 turnos | N21: =COUNTIF(C25:I25,"Ausente") -> 0 | O21: =IF($A21="","",IF($Q21="Horas",TEXT($U21,"[h]:mm")&" hs",$V21&IF($V21=1," turno"," turnos"))) -> 12 turnos | Q21: =IFERROR(INDEX(Equipo!$D$5:$D$14,3)&"","") -> Turnos | R21: =N(INDEX(Equipo!$E$5:$E$14,3)) -> 1 | S21: =SUMPRODUCT(C26:I26*(C25:I25="Feriado")) -> 0.35416667 | T21: =COUNTIFS(C25:I25,"Feriado",C21:I21,"<>")+COUNTIFS(C25:I25,"Feriado",C23:I23,"<>") -> 2 | U21: =N(J21)+L21*R21+S21 -> 1.3541667 | V21: =K21+L21+T21 -> 12
A22: =IF($A21="","",INDEX(Equipo!$C$5:$C$14,3)&"") -> Encargada | B22: Mañana · salida | C22: 0.58333333 | D22: 0.58333333 | F22: 0.58333333 | G22: 0.58333333 | H22: 0.58333333
A23: =IF($A21="","","Cobra por "&LOWER(INDEX(Equipo!$D$5:$D$14,3))) -> Cobra por turnos | B23: Noche · entrada | C23: 0.79166667 | F23: 0.79166667 | H23: 0.79166667 | I23: 0.79166667
B24: Noche · salida | C24: 0.97916667 | F24: 0.97916667 | H24: 0.020833333 | I24: 0.97916667
B25: Estado | C25: Feriado | E25: OFF
B26: Horas del día | C26: =IF(AND(C25<>"",C25<>"Feriado"),0,IF(AND(C21<>"",C22<>""),MOD(C22-C21,1),0)+IF(AND(C23<>"",C24<>""),MOD(C24-C23,1),0)) -> 0.35416667 | D26: =IF(AND(D25<>"",D25<>"Feriado"),0,IF(AND(D21<>"",D22<>""),MOD(D22-D21,1),0)+IF(AND(D23<>"",D24<>""),MOD(D24-D23,1),0)) -> 0.16666667 | E26: =IF(AND(E25<>"",E25<>"Feriado"),0,IF(AND(E21<>"",E22<>""),MOD(E22-E21,1),0)+IF(AND(E23<>"",E24<>""),MOD(E24-E23,1),0)) -> 0 | F26: =IF(AND(F25<>"",F25<>"Feriado"),0,IF(AND(F21<>"",F22<>""),MOD(F22-F21,1),0)+IF(AND(F23<>"",F24<>""),MOD(F24-F23,1),0)) -> 0.35416667 | G26: =IF(AND(G25<>"",G25<>"Feriado"),0,IF(AND(G21<>"",G22<>""),MOD(G22-G21,1),0)+IF(AND(G23<>"",G24<>""),MOD(G24-G23,1),0)) -> 0.16666667 | H26: =IF(AND(H25<>"",H25<>"Feriado"),0,IF(AND(H21<>"",H22<>""),MOD(H22-H21,1),0)+IF(AND(H23<>"",H24<>""),MOD(H24-H23,1),0)) -> 0.39583333 | I26: =IF(AND(I25<>"",I25<>"Feriado"),0,IF(AND(I21<>"",I22<>""),MOD(I22-I21,1),0)+IF(AND(I23<>"",I24<>""),MOD(I24-I23,1),0)) -> 0.1875
A28: =IFERROR(INDEX(Equipo!$B$5:$B$14,4)&"","") -> Nicolás Paz | B28: Mañana · entrada | C28: 0.41666667 | D28: 0.41666667 | E28: 0.41666667 | F28: 0.41666667 | H28: 0.41666667 | I28: 0.41666667 | J28: =IF($Q28="Turnos","",SUM(C33:I33)) -> 1.375 | K28: =SUMPRODUCT(((C28:I28<>"")+(C30:I30<>""))*((C32:I32="")+(C32:I32="Feriado"))) -> 7 | L28: =COUNTIF(C32:I32,"OFF") -> 1 | M28: =IF($A28="","",IF($Q28="Horas",IF($S28=0,"–",TEXT($S28,"[h]:mm")&" hs"),IF($T28=0,"–",$T28&IF($T28=1," turno"," turnos")))) -> 5:00 hs | N28: =COUNTIF(C32:I32,"Ausente") -> 0 | O28: =IF($A28="","",IF($Q28="Horas",TEXT($U28,"[h]:mm")&" hs",$V28&IF($V28=1," turno"," turnos"))) -> 42:30 hs | Q28: =IFERROR(INDEX(Equipo!$D$5:$D$14,4)&"","") -> Horas | R28: =N(INDEX(Equipo!$E$5:$E$14,4)) -> 0.1875 | S28: =SUMPRODUCT(C33:I33*(C32:I32="Feriado")) -> 0.20833333 | T28: =COUNTIFS(C32:I32,"Feriado",C28:I28,"<>")+COUNTIFS(C32:I32,"Feriado",C30:I30,"<>") -> 1 | U28: =N(J28)+L28*R28+S28 -> 1.7708333 | V28: =K28+L28+T28 -> 9
A29: =IF($A28="","",INDEX(Equipo!$C$5:$C$14,4)&"") -> Staff | B29: Mañana · salida | C29: 0.625 | D29: 0.625 | E29: 0.625 | F29: 0.625 | H29: 0.625 | I29: 0.58333333
A30: =IF($A28="","","Cobra por "&LOWER(INDEX(Equipo!$D$5:$D$14,4))) -> Cobra por horas | B30: Noche · entrada | H30: 0.79166667
B31: Noche · salida | H31: 0.95833333
B32: Estado | C32: Feriado | G32: OFF
B33: Horas del día | C33: =IF(AND(C32<>"",C32<>"Feriado"),0,IF(AND(C28<>"",C29<>""),MOD(C29-C28,1),0)+IF(AND(C30<>"",C31<>""),MOD(C31-C30,1),0)) -> 0.20833333 | D33: =IF(AND(D32<>"",D32<>"Feriado"),0,IF(AND(D28<>"",D29<>""),MOD(D29-D28,1),0)+IF(AND(D30<>"",D31<>""),MOD(D31-D30,1),0)) -> 0.20833333 | E33: =IF(AND(E32<>"",E32<>"Feriado"),0,IF(AND(E28<>"",E29<>""),MOD(E29-E28,1),0)+IF(AND(E30<>"",E31<>""),MOD(E31-E30,1),0)) -> 0.20833333 | F33: =IF(AND(F32<>"",F32<>"Feriado"),0,IF(AND(F28<>"",F29<>""),MOD(F29-F28,1),0)+IF(AND(F30<>"",F31<>""),MOD(F31-F30,1),0)) -> 0.20833333 | G33: =IF(AND(G32<>"",G32<>"Feriado"),0,IF(AND(G28<>"",G29<>""),MOD(G29-G28,1),0)+IF(AND(G30<>"",G31<>""),MOD(G31-G30,1),0)) -> 0 | H33: =IF(AND(H32<>"",H32<>"Feriado"),0,IF(AND(H28<>"",H29<>""),MOD(H29-H28,1),0)+IF(AND(H30<>"",H31<>""),MOD(H31-H30,1),0)) -> 0.375 | I33: =IF(AND(I32<>"",I32<>"Feriado"),0,IF(AND(I28<>"",I29<>""),MOD(I29-I28,1),0)+IF(AND(I30<>"",I31<>""),MOD(I31-I30,1),0)) -> 0.16666667
A35: =IFERROR(INDEX(Equipo!$B$5:$B$14,5)&"","") -> Paula Medina | B35: Mañana · entrada | D35: 0.35416667 | E35: 0.35416667 | G35: 0.35416667 | H35: 0.35416667 | J35: =IF($Q35="Turnos","",SUM(C40:I40)) -> 0.85416667 | K35: =SUMPRODUCT(((C35:I35<>"")+(C37:I37<>""))*((C39:I39="")+(C39:I39="Feriado"))) -> 4 | L35: =COUNTIF(C39:I39,"OFF") -> 1 | M35: =IF($A35="","",IF($Q35="Horas",IF($S35=0,"–",TEXT($S35,"[h]:mm")&" hs"),IF($T35=0,"–",$T35&IF($T35=1," turno"," turnos")))) -> – | N35: =COUNTIF(C39:I39,"Ausente") -> 0 | O35: =IF($A35="","",IF($Q35="Horas",TEXT($U35,"[h]:mm")&" hs",$V35&IF($V35=1," turno"," turnos"))) -> 25:00 hs | Q35: =IFERROR(INDEX(Equipo!$D$5:$D$14,5)&"","") -> Horas | R35: =N(INDEX(Equipo!$E$5:$E$14,5)) -> 0.1875 | S35: =SUMPRODUCT(C40:I40*(C39:I39="Feriado")) -> 0 | T35: =COUNTIFS(C39:I39,"Feriado",C35:I35,"<>")+COUNTIFS(C39:I39,"Feriado",C37:I37,"<>") -> 0 | U35: =N(J35)+L35*R35+S35 -> 1.0416667 | V35: =K35+L35+T35 -> 5
A36: =IF($A35="","",INDEX(Equipo!$C$5:$C$14,5)&"") -> Staff | B36: Mañana · salida | D36: 0.5625 | E36: 0.5625 | G36: 0.5625 | H36: 0.58333333
A37: =IF($A35="","","Cobra por "&LOWER(INDEX(Equipo!$D$5:$D$14,5))) -> Cobra por horas | B37: Noche · entrada
B38: Noche · salida
B39: Estado | C39: OFF | F39: Ausente justificado
B40: Horas del día | C40: =IF(AND(C39<>"",C39<>"Feriado"),0,IF(AND(C35<>"",C36<>""),MOD(C36-C35,1),0)+IF(AND(C37<>"",C38<>""),MOD(C38-C37,1),0)) -> 0 | D40: =IF(AND(D39<>"",D39<>"Feriado"),0,IF(AND(D35<>"",D36<>""),MOD(D36-D35,1),0)+IF(AND(D37<>"",D38<>""),MOD(D38-D37,1),0)) -> 0.20833333 | E40: =IF(AND(E39<>"",E39<>"Feriado"),0,IF(AND(E35<>"",E36<>""),MOD(E36-E35,1),0)+IF(AND(E37<>"",E38<>""),MOD(E38-E37,1),0)) -> 0.20833333 | F40: =IF(AND(F39<>"",F39<>"Feriado"),0,IF(AND(F35<>"",F36<>""),MOD(F36-F35,1),0)+IF(AND(F37<>"",F38<>""),MOD(F38-F37,1),0)) -> 0 | G40: =IF(AND(G39<>"",G39<>"Feriado"),0,IF(AND(G35<>"",G36<>""),MOD(G36-G35,1),0)+IF(AND(G37<>"",G38<>""),MOD(G38-G37,1),0)) -> 0.20833333 | H40: =IF(AND(H39<>"",H39<>"Feriado"),0,IF(AND(H35<>"",H36<>""),MOD(H36-H35,1),0)+IF(AND(H37<>"",H38<>""),MOD(H38-H37,1),0)) -> 0.22916667 | I40: =IF(AND(I39<>"",I39<>"Feriado"),0,IF(AND(I35<>"",I36<>""),MOD(I36-I35,1),0)+IF(AND(I37<>"",I38<>""),MOD(I38-I37,1),0)) -> 0
A42: =IFERROR(INDEX(Equipo!$B$5:$B$14,6)&"","") -> Tomás Godoy | B42: Mañana · entrada | C42: 0.58333333 | D42: 0.58333333 | E42: 0.58333333 | G42: 0.58333333 | I42: 0.58333333 | J42: =IF($Q42="Turnos","",SUM(C47:I47)) -> 1.2083333 | K42: =SUMPRODUCT(((C42:I42<>"")+(C44:I44<>""))*((C46:I46="")+(C46:I46="Feriado"))) -> 5 | L42: =COUNTIF(C46:I46,"OFF") -> 1 | M42: =IF($A42="","",IF($Q42="Horas",IF($S42=0,"–",TEXT($S42,"[h]:mm")&" hs"),IF($T42=0,"–",$T42&IF($T42=1," turno"," turnos")))) -> 6:00 hs | N42: =COUNTIF(C46:I46,"Ausente") -> 1 | O42: =IF($A42="","",IF($Q42="Horas",TEXT($U42,"[h]:mm")&" hs",$V42&IF($V42=1," turno"," turnos"))) -> 39:30 hs | Q42: =IFERROR(INDEX(Equipo!$D$5:$D$14,6)&"","") -> Horas | R42: =N(INDEX(Equipo!$E$5:$E$14,6)) -> 0.1875 | S42: =SUMPRODUCT(C47:I47*(C46:I46="Feriado")) -> 0.25 | T42: =COUNTIFS(C46:I46,"Feriado",C42:I42,"<>")+COUNTIFS(C46:I46,"Feriado",C44:I44,"<>") -> 1 | U42: =N(J42)+L42*R42+S42 -> 1.6458333 | V42: =K42+L42+T42 -> 7
A43: =IF($A42="","",INDEX(Equipo!$C$5:$C$14,6)&"") -> Staff | B43: Mañana · salida | C43: 0.83333333 | D43: 0.83333333 | E43: 0.83333333 | G43: 0.83333333 | I43: 0.79166667
A44: =IF($A42="","","Cobra por "&LOWER(INDEX(Equipo!$D$5:$D$14,6))) -> Cobra por horas | B44: Noche · entrada
B45: Noche · salida
B46: Estado | C46: Feriado | F46: Ausente | H46: OFF
...

Sheet Resumen
A1: Resumen de la semana
A2: Semana | B2: =Semana!I2 -> 46349 | C2: al | D2: =Semana!K2 -> 46355 | E2: =Semana!E2 -> Mercado Central
A4: Colaborador | B4: Puesto | C4: Cobra por | D4: Trabajado | E4: OFF | F4: Feriado | G4: Ausentes | H4: Vacaciones | I4: Total a liquidar | J4: Observaciones
A5: =Semana!A7 -> Sofía Ríos | B5: =IF(A5="","",INDEX(Equipo!$C$5:$C$14,1)&"") -> Encargada | C5: =IF(A5="","",INDEX(Equipo!$D$5:$D$14,1)&"") -> Turnos | D5: =IF(A5="","",IF(C5="Horas",TEXT(Semana!J7,"[h]:mm")&" hs",Semana!K7&IF(Semana!K7=1," turno"," turnos"))) -> 6 turnos | E5: =IF(A5="","",IF(Semana!L7=0,"–",IF(C5="Horas",TEXT(Semana!L7*Semana!R7,"[h]:mm")&" hs ("&Semana!L7&IF(Semana!L7=1," día)"," días)"),Semana!L7&IF(Semana!L7=1," turno"," turnos")))) -> 1 turno | F5: =IF(A5="","",Semana!M7) -> 1 turno | G5: =IF(A5="","",IF(Semana!N7=0,"–",Semana!N7&IF(Semana!N7=1," día"," días"))) -> – | H5: =IF(A5="","",IF(COUNTIF(Semana!C11:I11,"Vacaciones")=0,"–",COUNTIF(Semana!C11:I11,"Vacaciones")&" días")) -> – | I5: =IF(A5="","",Semana!O7) -> 8 turnos
A6: =Semana!A14 -> Lucas Ferreyra | B6: =IF(A6="","",INDEX(Equipo!$C$5:$C$14,2)&"") -> Encargado | C6: =IF(A6="","",INDEX(Equipo!$D$5:$D$14,2)&"") -> Turnos | D6: =IF(A6="","",IF(C6="Horas",TEXT(Semana!J14,"[h]:mm")&" hs",Semana!K14&IF(Semana!K14=1," turno"," turnos"))) -> 6 turnos | E6: =IF(A6="","",IF(Semana!L14=0,"–",IF(C6="Horas",TEXT(Semana!L14*Semana!R14,"[h]:mm")&" hs ("&Semana!L14&IF(Semana!L14=1," día)"," días)"),Semana!L14&IF(Semana!L14=1," turno"," turnos")))) -> 1 turno | F6: =IF(A6="","",Semana!M14) -> – | G6: =IF(A6="","",IF(Semana!N14=0,"–",Semana!N14&IF(Semana!N14=1," día"," días"))) -> – | H6: =IF(A6="","",IF(COUNTIF(Semana!C18:I18,"Vacaciones")=0,"–",COUNTIF(Semana!C18:I18,"Vacaciones")&" días")) -> – | I6: =IF(A6="","",Semana!O14) -> 7 turnos
A7: =Semana!A21 -> Brenda Quiroga | B7: =IF(A7="","",INDEX(Equipo!$C$5:$C$14,3)&"") -> Encargada | C7: =IF(A7="","",INDEX(Equipo!$D$5:$D$14,3)&"") -> Turnos | D7: =IF(A7="","",IF(C7="Horas",TEXT(Semana!J21,"[h]:mm")&" hs",Semana!K21&IF(Semana!K21=1," turno"," turnos"))) -> 9 turnos | E7: =IF(A7="","",IF(Semana!L21=0,"–",IF(C7="Horas",TEXT(Semana!L21*Semana!R21,"[h]:mm")&" hs ("&Semana!L21&IF(Semana!L21=1," día)"," días)"),Semana!L21&IF(Semana!L21=1," turno"," turnos")))) -> 1 turno | F7: =IF(A7="","",Semana!M21) -> 2 turnos | G7: =IF(A7="","",IF(Semana!N21=0,"–",Semana!N21&IF(Semana!N21=1," día"," días"))) -> – | H7: =IF(A7="","",IF(COUNTIF(Semana!C25:I25,"Vacaciones")=0,"–",COUNTIF(Semana!C25:I25,"Vacaciones")&" días")) -> – | I7: =IF(A7="","",Semana!O21) -> 12 turnos
A8: =Semana!A28 -> Nicolás Paz | B8: =IF(A8="","",INDEX(Equipo!$C$5:$C$14,4)&"") -> Staff | C8: =IF(A8="","",INDEX(Equipo!$D$5:$D$14,4)&"") -> Horas | D8: =IF(A8="","",IF(C8="Horas",TEXT(Semana!J28,"[h]:mm")&" hs",Semana!K28&IF(Semana!K28=1," turno"," turnos"))) -> 33:00 hs | E8: =IF(A8="","",IF(Semana!L28=0,"–",IF(C8="Horas",TEXT(Semana!L28*Semana!R28,"[h]:mm")&" hs ("&Semana!L28&IF(Semana!L28=1," día)"," días)"),Semana!L28&IF(Semana!L28=1," turno"," turnos")))) -> 4:30 hs (1 día) | F8: =IF(A8="","",Semana!M28) -> 5:00 hs | G8: =IF(A8="","",IF(Semana!N28=0,"–",Semana!N28&IF(Semana!N28=1," día"," días"))) -> – | H8: =IF(A8="","",IF(COUNTIF(Semana!C32:I32,"Vacaciones")=0,"–",COUNTIF(Semana!C32:I32,"Vacaciones")&" días")) -> – | I8: =IF(A8="","",Semana!O28) -> 42:30 hs
A9: =Semana!A35 -> Paula Medina | B9: =IF(A9="","",INDEX(Equipo!$C$5:$C$14,5)&"") -> Staff | C9: =IF(A9="","",INDEX(Equipo!$D$5:$D$14,5)&"") -> Horas | D9: =IF(A9="","",IF(C9="Horas",TEXT(Semana!J35,"[h]:mm")&" hs",Semana!K35&IF(Semana!K35=1," turno"," turnos"))) -> 20:30 hs | E9: =IF(A9="","",IF(Semana!L35=0,"–",IF(C9="Horas",TEXT(Semana!L35*Semana!R35,"[h]:mm")&" hs ("&Semana!L35&IF(Semana!L35=1," día)"," días)"),Semana!L35&IF(Semana!L35=1," turno"," turnos")))) -> 4:30 hs (1 día) | F9: =IF(A9="","",Semana!M35) -> – | G9: =IF(A9="","",IF(Semana!N35=0,"–",Semana!N35&IF(Semana!N35=1," día"," días"))) -> – | H9: =IF(A9="","",IF(COUNTIF(Semana!C39:I39,"Vacaciones")=0,"–",COUNTIF(Semana!C39:I39,"Vacaciones")&" días")) -> – | I9: =IF(A9="","",Semana!O35) -> 25:00 hs
A10: =Semana!A42 -> Tomás Godoy | B10: =IF(A10="","",INDEX(Equipo!$C$5:$C$14,6)&"") -> Staff | C10: =IF(A10="","",INDEX(Equipo!$D$5:$D$14,6)&"") -> Horas | D10: =IF(A10="","",IF(C10="Horas",TEXT(Semana!J42,"[h]:mm")&" hs",Semana!K42&IF(Semana!K42=1," turno"," turnos"))) -> 29:00 hs | E10: =IF(A10="","",IF(Semana!L42=0,"–",IF(C10="Horas",TEXT(Semana!L42*Semana!R42,"[h]:mm")&" hs ("&Semana!L42&IF(Semana!L42=1," día)"," días)"),Semana!L42&IF(Semana!L42=1," turno"," turnos")))) -> 4:30 hs (1 día) | F10: =IF(A10="","",Semana!M42) -> 6:00 hs | G10: =IF(A10="","",IF(Semana!N42=0,"–",Semana!N42&IF(Semana!N42=1," día"," días"))) -> 1 día | H10: =IF(A10="","",IF(COUNTIF(Semana!C46:I46,"Vacaciones")=0,"–",COUNTIF(Semana!C46:I46,"Vacaciones")&" días")) -> – | I10: =IF(A10="","",Semana!O42) -> 39:30 hs
A11: =Semana!A49 -> Valentina Sosa | B11: =IF(A11="","",INDEX(Equipo!$C$5:$C$14,7)&"") -> Staff | C11: =IF(A11="","",INDEX(Equipo!$D$5:$D$14,7)&"") -> Horas | D11: =IF(A11="","",IF(C11="Horas",TEXT(Semana!J49,"[h]:mm")&" hs",Semana!K49&IF(Semana!K49=1," turno"," turnos"))) -> 26:30 hs | E11: =IF(A11="","",IF(Semana!L49=0,"–",IF(C11="Horas",TEXT(Semana!L49*Semana!R49,"[h]:mm")&" hs ("&Semana!L49&IF(Semana!L49=1," día)"," días)"),Semana!L49&IF(Semana!L49=1," turno"," turnos")))) -> 4:30 hs (1 día) | F11: =IF(A11="","",Semana!M49) -> 5:00 hs | G11: =IF(A11="","",IF(Semana!N49=0,"–",Semana!N49&IF(Semana!N49=1," día"," días"))) -> – | H11: =IF(A11="","",IF(COUNTIF(Semana!C53:I53,"Vacaciones")=0,"–",COUNTIF(Semana!C53:I53,"Vacaciones")&" días")) -> – | I11: =IF(A11="","",Semana!O49) -> 36:00 hs
A12: =Semana!A56 -> Rocío Álvarez | B12: =IF(A12="","",INDEX(Equipo!$C$5:$C$14,8)&"") -> Staff | C12: =IF(A12="","",INDEX(Equipo!$D$5:$D$14,8)&"") -> Horas | D12: =IF(A12="","",IF(C12="Horas",TEXT(Semana!J56,"[h]:mm")&" hs",Semana!K56&IF(Semana!K56=1," turno"," turnos"))) -> 16:00 hs | E12: =IF(A12="","",IF(Semana!L56=0,"–",IF(C12="Horas",TEXT(Semana!L56*Semana!R56,"[h]:mm")&" hs ("&Semana!L56&IF(Semana!L56=1," día)"," días)"),Semana!L56&IF(Semana!L56=1," turno"," turnos")))) -> 4:30 hs (1 día) | F12: =IF(A12="","",Semana!M56) -> – | G12: =IF(A12="","",IF(Semana!N56=0,"–",Semana!N56&IF(Semana!N56=1," día"," días"))) -> – | H12: =IF(A12="","",IF(COUNTIF(Semana!C60:I60,"Vacaciones")=0,"–",COUNTIF(Semana!C60:I60,"Vacaciones")&" días")) -> 3 días | I12: =IF(A12="","",Semana!O56) -> 20:30 hs
A13: =Semana!A63 | B13: =IF(A13="","",INDEX(Equipo!$C$5:$C$14,9)&"") | C13: =IF(A13="","",INDEX(Equipo!$D$5:$D$14,9)&"") | D13: =IF(A13="","",IF(C13="Horas",TEXT(Semana!J63,"[h]:mm")&" hs",Semana!K63&IF(Semana!K63=1," turno"," turnos"))) | E13: =IF(A13="","",IF(Semana!L63=0,"–",IF(C13="Horas",TEXT(Semana!L63*Semana!R63,"[h]:mm")&" hs ("&Semana!L63&IF(Semana!L63=1," día)"," días)"),Semana!L63&IF(Semana!L63=1," turno"," turnos")))) | F13: =IF(A13="","",Semana!M63) | G13: =IF(A13="","",IF(Semana!N63=0,"–",Semana!N63&IF(Semana!N63=1," día"," días"))) | H13: =IF(A13="","",IF(COUNTIF(Semana!C67:I67,"Vacaciones")=0,"–",COUNTIF(Semana!C67:I67,"Vacaciones")&" días")) | I13: =IF(A13="","",Semana!O63)
A14: =Semana!A70 | B14: =IF(A14="","",INDEX(Equipo!$C$5:$C$14,10)&"") | C14: =IF(A14="","",INDEX(Equipo!$D$5:$D$14,10)&"") | D14: =IF(A14="","",IF(C14="Horas",TEXT(Semana!J70,"[h]:mm")&" hs",Semana!K70&IF(Semana!K70=1," turno"," turnos"))) | E14: =IF(A14="","",IF(Semana!L70=0,"–",IF(C14="Horas",TEXT(Semana!L70*Semana!R70,"[h]:mm")&" hs ("&Semana!L70&IF(Semana!L70=1," día)"," días)"),Semana!L70&IF(Semana!L70=1," turno"," turnos")))) | F14: =IF(A14="","",Semana!M70) | G14: =IF(A14="","",IF(Semana!N70=0,"–",Semana!N70&IF(Semana!N70=1," día"," días"))) | H14: =IF(A14="","",IF(COUNTIF(Semana!C74:I74,"Vacaciones")=0,"–",COUNTIF(Semana!C74:I74,"Vacaciones")&" días")) | I14: =IF(A14="","",Semana!O70)
A16: Trabajado, OFF y feriado se suman en «Total a liquidar» (en horas o turnos según cómo cobra cada persona). Ausentes y vacaciones se informan en días.

Sheet Equipo
A1: Equipo
A2: Cargá a cada persona una sola vez. La planilla semanal toma los nombres de acá (hasta 10).
A4: # | B4: Colaborador | C4: Puesto | D4: Cobra por | E4: OFF (horas que paga) | F4: Notas
A5: 1 | B5: Sofía Ríos | C5: Encargada | D5: Turnos | E5: 1 | F5: Turno mañana
A6: 2 | B6: Lucas Ferreyra | C6: Encargado | D6: Turnos | E6: 1 | F6: Turno noche
A7: 3 | B7: Brenda Quiroga | C7: Encargada | D7: Turnos | E7: 1 | F7: Mañana y noche
A8: 4 | B8: Nicolás Paz | C8: Staff | D8: Horas | E8: 0.1875 | F8: Caja
A9: 5 | B9: Paula Medina | C9: Staff | D9: Horas | E9: 0.1875 | F9: Reposición
A10: 6 | B10: Tomás Godoy | C10: Staff | D10: Horas | E10: 0.1875 | F10: Depósito
A11: 7 | B11: Valentina Sosa | C11: Staff | D11: Horas | E11: 0.1875 | F11: Atención al público
A12: 8 | B12: Rocío Álvarez | C12: Staff | D12: Horas | E12: 0.1875 | F12: Fines de semana
A13: 9
A14: 10
B16: «OFF» solo se usa en horas para quienes cobran por horas (ej. 4:30). Quienes cobran por turnos suman 1 turno por OFF.

Sheet Feriados
A1: Feriados
A2: Los feriados de esta lista se pintan en ámbar en el encabezado de la semana como recordatorio. Para pagarlo, elegí «Feriado» en el Estado de quien trabajó ese día.
A4: Fecha | B4: Motivo | C4: Tipo
A5: 46023 | B5: Año Nuevo | C5: Feriado
A6: 46069 | B6: Carnaval | C6: Feriado
A7: 46070 | B7: Carnaval | C7: Feriado
A8: 46104 | B8: Día no laborable con fines turísticos | C8: No laborable
A9: 46105 | B9: Día Nacional de la Memoria por la Verdad y la Justicia | C9: Feriado
A10: 46114 | B10: Día del Veterano y de los Caídos en la Guerra de Malvinas | C10: Feriado
A11: 46115 | B11: Viernes Santo | C11: Feriado
A12: 46143 | B12: Día del Trabajador | C12: Feriado
A13: 46167 | B13: Día de la Revolución de Mayo | C13: Feriado
A14: 46188 | B14: Paso a la Inmortalidad del Gral. Martín Miguel de Güemes (trasladado) | C14: Feriado
A15: 46193 | B15: Paso a la Inmortalidad del Gral. Manuel Belgrano | C15: Feriado
A16: 46212 | B16: Día de la Independencia | C16: Feriado
... A23: 46381 | B23: Navidad | C23: Feriado
